[2020-11-12 00:11:40,980] [log.py:228] [log:log_response] [WARNING]- Not Found: /robots.txt
[2020-11-12 00:16:45,469] [log.py:228] [log:log_response] [ERROR]- Internal Server Error: /new_user/activity/1.html
Traceback (most recent call last):
  File "/opt/env_list/env_myblog/lib/python3.6/site-packages/django/core/handlers/exception.py", line 34, in inner
    response = get_response(request)
  File "/opt/env_list/env_myblog/lib/python3.6/site-packages/django/core/handlers/base.py", line 126, in _get_response
    response = self.process_exception_by_middleware(e, request)
  File "/opt/env_list/env_myblog/lib/python3.6/site-packages/django/core/handlers/base.py", line 124, in _get_response
    response = wrapped_callback(request, *callback_args, **callback_kwargs)
  File "./new_user/views.py", line 98, in activityView
    BadmintonActivity.objects.values(fk=int(number))
  File "/opt/env_list/env_myblog/lib/python3.6/site-packages/django/db/models/manager.py", line 82, in manager_method
    return getattr(self.get_queryset(), name)(*args, **kwargs)
  File "/opt/env_list/env_myblog/lib/python3.6/site-packages/django/db/models/query.py", line 750, in values
    clone = self._values(*fields, **expressions)
  File "/opt/env_list/env_myblog/lib/python3.6/site-packages/django/db/models/query.py", line 743, in _values
    clone = clone.annotate(**expressions)
  File "/opt/env_list/env_myblog/lib/python3.6/site-packages/django/db/models/query.py", line 979, in annotate
    self._validate_values_are_expressions(args + tuple(kwargs.values()), method_name='annotate')
  File "/opt/env_list/env_myblog/lib/python3.6/site-packages/django/db/models/query.py", line 1254, in _validate_values_are_expressions
    ', '.join(invalid_args),
TypeError: QuerySet.annotate() received non-expression(s): 1.
[2020-11-12 00:24:43,635] [log.py:228] [log:log_response] [ERROR]- Internal Server Error: /new_user/activity/2.html
Traceback (most recent call last):
  File "/opt/env_list/env_myblog/lib/python3.6/site-packages/django/template/base.py", line 470, in parse
    compile_func = self.tags[command]
KeyError: 'context'

During handling of the above exception, another exception occurred:

Traceback (most recent call last):
  File "/opt/env_list/env_myblog/lib/python3.6/site-packages/django/core/handlers/exception.py", line 34, in inner
    response = get_response(request)
  File "/opt/env_list/env_myblog/lib/python3.6/site-packages/django/core/handlers/base.py", line 126, in _get_response
    response = self.process_exception_by_middleware(e, request)
  File "/opt/env_list/env_myblog/lib/python3.6/site-packages/django/core/handlers/base.py", line 124, in _get_response
    response = wrapped_callback(request, *callback_args, **callback_kwargs)
  File "./new_user/views.py", line 110, in activityView
    return render(request, 'activity.html', context)
  File "/opt/env_list/env_myblog/lib/python3.6/site-packages/django/shortcuts.py", line 36, in render
    content = loader.render_to_string(template_name, context, request, using=using)
  File "/opt/env_list/env_myblog/lib/python3.6/site-packages/django/template/loader.py", line 61, in render_to_string
    template = get_template(template_name, using=using)
  File "/opt/env_list/env_myblog/lib/python3.6/site-packages/django/template/loader.py", line 15, in get_template
    return engine.get_template(template_name)
  File "/opt/env_list/env_myblog/lib/python3.6/site-packages/django/template/backends/django.py", line 34, in get_template
    return Template(self.engine.get_template(template_name), self)
  File "/opt/env_list/env_myblog/lib/python3.6/site-packages/django/template/engine.py", line 144, in get_template
    template, origin = self.find_template(template_name)
  File "/opt/env_list/env_myblog/lib/python3.6/site-packages/django/template/engine.py", line 126, in find_template
    template = loader.get_template(name, skip=skip)
  File "/opt/env_list/env_myblog/lib/python3.6/site-packages/django/template/loaders/base.py", line 30, in get_template
    contents, origin, origin.template_name, self.engine,
  File "/opt/env_list/env_myblog/lib/python3.6/site-packages/django/template/base.py", line 156, in __init__
    self.nodelist = self.compile_nodelist()
  File "/opt/env_list/env_myblog/lib/python3.6/site-packages/django/template/base.py", line 194, in compile_nodelist
    return parser.parse()
  File "/opt/env_list/env_myblog/lib/python3.6/site-packages/django/template/base.py", line 478, in parse
    raise self.error(token, e)
  File "/opt/env_list/env_myblog/lib/python3.6/site-packages/django/template/base.py", line 476, in parse
    compiled_result = compile_func(self, token)
  File "/opt/env_list/env_myblog/lib/python3.6/site-packages/django/template/defaulttags.py", line 951, in do_if
    nodelist = parser.parse(('elif', 'else', 'endif'))
  File "/opt/env_list/env_myblog/lib/python3.6/site-packages/django/template/base.py", line 472, in parse
    self.invalid_block_tag(token, command, parse_until)
  File "/opt/env_list/env_myblog/lib/python3.6/site-packages/django/template/base.py", line 528, in invalid_block_tag
    get_text_list(["'%s'" % p for p in parse_until], 'or'),
django.template.exceptions.TemplateSyntaxError: Invalid block tag on line 35: 'context', expected 'elif'ï¼Œ'else' or 'endif'. Did you forget to register or load this tag?
[2020-11-12 00:31:46,929] [log.py:228] [log:log_response] [ERROR]- Internal Server Error: /new_user/activity/1.html
Traceback (most recent call last):
  File "/opt/env_list/env_myblog/lib/python3.6/site-packages/django/core/handlers/exception.py", line 34, in inner
    response = get_response(request)
  File "/opt/env_list/env_myblog/lib/python3.6/site-packages/django/core/handlers/base.py", line 126, in _get_response
    response = self.process_exception_by_middleware(e, request)
  File "/opt/env_list/env_myblog/lib/python3.6/site-packages/django/core/handlers/base.py", line 124, in _get_response
    response = wrapped_callback(request, *callback_args, **callback_kwargs)
  File "./new_user/views.py", line 109, in activityView
    return render(request, 'activity.html', locals())
  File "/opt/env_list/env_myblog/lib/python3.6/site-packages/django/shortcuts.py", line 36, in render
    content = loader.render_to_string(template_name, context, request, using=using)
  File "/opt/env_list/env_myblog/lib/python3.6/site-packages/django/template/loader.py", line 61, in render_to_string
    template = get_template(template_name, using=using)
  File "/opt/env_list/env_myblog/lib/python3.6/site-packages/django/template/loader.py", line 15, in get_template
    return engine.get_template(template_name)
  File "/opt/env_list/env_myblog/lib/python3.6/site-packages/django/template/backends/django.py", line 34, in get_template
    return Template(self.engine.get_template(template_name), self)
  File "/opt/env_list/env_myblog/lib/python3.6/site-packages/django/template/engine.py", line 144, in get_template
    template, origin = self.find_template(template_name)
  File "/opt/env_list/env_myblog/lib/python3.6/site-packages/django/template/engine.py", line 126, in find_template
    template = loader.get_template(name, skip=skip)
  File "/opt/env_list/env_myblog/lib/python3.6/site-packages/django/template/loaders/base.py", line 30, in get_template
    contents, origin, origin.template_name, self.engine,
  File "/opt/env_list/env_myblog/lib/python3.6/site-packages/django/template/base.py", line 156, in __init__
    self.nodelist = self.compile_nodelist()
  File "/opt/env_list/env_myblog/lib/python3.6/site-packages/django/template/base.py", line 194, in compile_nodelist
    return parser.parse()
  File "/opt/env_list/env_myblog/lib/python3.6/site-packages/django/template/base.py", line 478, in parse
    raise self.error(token, e)
  File "/opt/env_list/env_myblog/lib/python3.6/site-packages/django/template/base.py", line 476, in parse
    compiled_result = compile_func(self, token)
  File "/opt/env_list/env_myblog/lib/python3.6/site-packages/django/template/defaulttags.py", line 951, in do_if
    nodelist = parser.parse(('elif', 'else', 'endif'))
  File "/opt/env_list/env_myblog/lib/python3.6/site-packages/django/template/base.py", line 478, in parse
    raise self.error(token, e)
  File "/opt/env_list/env_myblog/lib/python3.6/site-packages/django/template/base.py", line 476, in parse
    compiled_result = compile_func(self, token)
  File "/opt/env_list/env_myblog/lib/python3.6/site-packages/django/template/defaulttags.py", line 810, in do_for
    nodelist_loop = parser.parse(('empty', 'endfor',))
  File "/opt/env_list/env_myblog/lib/python3.6/site-packages/django/template/base.py", line 449, in parse
    raise self.error(token, e)
  File "/opt/env_list/env_myblog/lib/python3.6/site-packages/django/template/base.py", line 447, in parse
    filter_expression = self.compile_filter(token.contents)
  File "/opt/env_list/env_myblog/lib/python3.6/site-packages/django/template/base.py", line 563, in compile_filter
    return FilterExpression(token, self)
  File "/opt/env_list/env_myblog/lib/python3.6/site-packages/django/template/base.py", line 663, in __init__
    "from '%s'" % (token[upto:], token))
django.template.exceptions.TemplateSyntaxError: Could not parse the remainder: '[i]' from 'user_info[i]'
[2020-11-12 00:37:00,087] [log.py:228] [log:log_response] [ERROR]- Internal Server Error: /new_user/activity/1.html
Traceback (most recent call last):
  File "/opt/env_list/env_myblog/lib/python3.6/site-packages/django/core/handlers/exception.py", line 34, in inner
    response = get_response(request)
  File "/opt/env_list/env_myblog/lib/python3.6/site-packages/django/core/handlers/base.py", line 126, in _get_response
    response = self.process_exception_by_middleware(e, request)
  File "/opt/env_list/env_myblog/lib/python3.6/site-packages/django/core/handlers/base.py", line 124, in _get_response
    response = wrapped_callback(request, *callback_args, **callback_kwargs)
  File "./new_user/views.py", line 109, in activityView
    return render(request, 'activity.html', locals())
  File "/opt/env_list/env_myblog/lib/python3.6/site-packages/django/shortcuts.py", line 36, in render
    content = loader.render_to_string(template_name, context, request, using=using)
  File "/opt/env_list/env_myblog/lib/python3.6/site-packages/django/template/loader.py", line 61, in render_to_string
    template = get_template(template_name, using=using)
  File "/opt/env_list/env_myblog/lib/python3.6/site-packages/django/template/loader.py", line 15, in get_template
    return engine.get_template(template_name)
  File "/opt/env_list/env_myblog/lib/python3.6/site-packages/django/template/backends/django.py", line 34, in get_template
    return Template(self.engine.get_template(template_name), self)
  File "/opt/env_list/env_myblog/lib/python3.6/site-packages/django/template/engine.py", line 144, in get_template
    template, origin = self.find_template(template_name)
  File "/opt/env_list/env_myblog/lib/python3.6/site-packages/django/template/engine.py", line 126, in find_template
    template = loader.get_template(name, skip=skip)
  File "/opt/env_list/env_myblog/lib/python3.6/site-packages/django/template/loaders/base.py", line 30, in get_template
    contents, origin, origin.template_name, self.engine,
  File "/opt/env_list/env_myblog/lib/python3.6/site-packages/django/template/base.py", line 156, in __init__
    self.nodelist = self.compile_nodelist()
  File "/opt/env_list/env_myblog/lib/python3.6/site-packages/django/template/base.py", line 194, in compile_nodelist
    return parser.parse()
  File "/opt/env_list/env_myblog/lib/python3.6/site-packages/django/template/base.py", line 478, in parse
    raise self.error(token, e)
  File "/opt/env_list/env_myblog/lib/python3.6/site-packages/django/template/base.py", line 476, in parse
    compiled_result = compile_func(self, token)
  File "/opt/env_list/env_myblog/lib/python3.6/site-packages/django/template/defaulttags.py", line 951, in do_if
    nodelist = parser.parse(('elif', 'else', 'endif'))
  File "/opt/env_list/env_myblog/lib/python3.6/site-packages/django/template/base.py", line 478, in parse
    raise self.error(token, e)
  File "/opt/env_list/env_myblog/lib/python3.6/site-packages/django/template/base.py", line 476, in parse
    compiled_result = compile_func(self, token)
  File "/opt/env_list/env_myblog/lib/python3.6/site-packages/django/template/defaulttags.py", line 809, in do_for
    sequence = parser.compile_filter(bits[in_index + 1])
  File "/opt/env_list/env_myblog/lib/python3.6/site-packages/django/template/base.py", line 563, in compile_filter
    return FilterExpression(token, self)
  File "/opt/env_list/env_myblog/lib/python3.6/site-packages/django/template/base.py", line 663, in __init__
    "from '%s'" % (token[upto:], token))
django.template.exceptions.TemplateSyntaxError: Could not parse the remainder: '()' from 'user_info.items()'
[2020-11-12 00:37:53,587] [log.py:228] [log:log_response] [ERROR]- Internal Server Error: /new_user/activity/1.html
Traceback (most recent call last):
  File "/opt/env_list/env_myblog/lib/python3.6/site-packages/django/core/handlers/exception.py", line 34, in inner
    response = get_response(request)
  File "/opt/env_list/env_myblog/lib/python3.6/site-packages/django/core/handlers/base.py", line 126, in _get_response
    response = self.process_exception_by_middleware(e, request)
  File "/opt/env_list/env_myblog/lib/python3.6/site-packages/django/core/handlers/base.py", line 124, in _get_response
    response = wrapped_callback(request, *callback_args, **callback_kwargs)
  File "./new_user/views.py", line 109, in activityView
    return render(request, 'activity.html', locals())
  File "/opt/env_list/env_myblog/lib/python3.6/site-packages/django/shortcuts.py", line 36, in render
    content = loader.render_to_string(template_name, context, request, using=using)
  File "/opt/env_list/env_myblog/lib/python3.6/site-packages/django/template/loader.py", line 61, in render_to_string
    template = get_template(template_name, using=using)
  File "/opt/env_list/env_myblog/lib/python3.6/site-packages/django/template/loader.py", line 15, in get_template
    return engine.get_template(template_name)
  File "/opt/env_list/env_myblog/lib/python3.6/site-packages/django/template/backends/django.py", line 34, in get_template
    return Template(self.engine.get_template(template_name), self)
  File "/opt/env_list/env_myblog/lib/python3.6/site-packages/django/template/engine.py", line 144, in get_template
    template, origin = self.find_template(template_name)
  File "/opt/env_list/env_myblog/lib/python3.6/site-packages/django/template/engine.py", line 126, in find_template
    template = loader.get_template(name, skip=skip)
  File "/opt/env_list/env_myblog/lib/python3.6/site-packages/django/template/loaders/base.py", line 30, in get_template
    contents, origin, origin.template_name, self.engine,
  File "/opt/env_list/env_myblog/lib/python3.6/site-packages/django/template/base.py", line 156, in __init__
    self.nodelist = self.compile_nodelist()
  File "/opt/env_list/env_myblog/lib/python3.6/site-packages/django/template/base.py", line 194, in compile_nodelist
    return parser.parse()
  File "/opt/env_list/env_myblog/lib/python3.6/site-packages/django/template/base.py", line 478, in parse
    raise self.error(token, e)
  File "/opt/env_list/env_myblog/lib/python3.6/site-packages/django/template/base.py", line 476, in parse
    compiled_result = compile_func(self, token)
  File "/opt/env_list/env_myblog/lib/python3.6/site-packages/django/template/defaulttags.py", line 951, in do_if
    nodelist = parser.parse(('elif', 'else', 'endif'))
  File "/opt/env_list/env_myblog/lib/python3.6/site-packages/django/template/base.py", line 478, in parse
    raise self.error(token, e)
  File "/opt/env_list/env_myblog/lib/python3.6/site-packages/django/template/base.py", line 476, in parse
    compiled_result = compile_func(self, token)
  File "/opt/env_list/env_myblog/lib/python3.6/site-packages/django/template/defaulttags.py", line 809, in do_for
    sequence = parser.compile_filter(bits[in_index + 1])
  File "/opt/env_list/env_myblog/lib/python3.6/site-packages/django/template/base.py", line 563, in compile_filter
    return FilterExpression(token, self)
  File "/opt/env_list/env_myblog/lib/python3.6/site-packages/django/template/base.py", line 663, in __init__
    "from '%s'" % (token[upto:], token))
django.template.exceptions.TemplateSyntaxError: Could not parse the remainder: '()' from 'user_info.keys()'
[2020-11-12 00:44:14,813] [log.py:228] [log:log_response] [ERROR]- Internal Server Error: /new_user/activity/2.html
Traceback (most recent call last):
  File "/opt/env_list/env_myblog/lib/python3.6/site-packages/django/core/handlers/exception.py", line 34, in inner
    response = get_response(request)
  File "/opt/env_list/env_myblog/lib/python3.6/site-packages/django/core/handlers/base.py", line 126, in _get_response
    response = self.process_exception_by_middleware(e, request)
  File "/opt/env_list/env_myblog/lib/python3.6/site-packages/django/core/handlers/base.py", line 124, in _get_response
    response = wrapped_callback(request, *callback_args, **callback_kwargs)
  File "./new_user/views.py", line 109, in activityView
    return render(request, 'activity.html', locals())
  File "/opt/env_list/env_myblog/lib/python3.6/site-packages/django/shortcuts.py", line 36, in render
    content = loader.render_to_string(template_name, context, request, using=using)
  File "/opt/env_list/env_myblog/lib/python3.6/site-packages/django/template/loader.py", line 62, in render_to_string
    return template.render(context, request)
  File "/opt/env_list/env_myblog/lib/python3.6/site-packages/django/template/backends/django.py", line 61, in render
    return self.template.render(context)
  File "/opt/env_list/env_myblog/lib/python3.6/site-packages/django/template/base.py", line 171, in render
    return self._render(context)
  File "/opt/env_list/env_myblog/lib/python3.6/site-packages/django/template/base.py", line 163, in _render
    return self.nodelist.render(context)
  File "/opt/env_list/env_myblog/lib/python3.6/site-packages/django/template/base.py", line 937, in render
    bit = node.render_annotated(context)
  File "/opt/env_list/env_myblog/lib/python3.6/site-packages/django/template/base.py", line 904, in render_annotated
    return self.render(context)
  File "/opt/env_list/env_myblog/lib/python3.6/site-packages/django/template/defaulttags.py", line 309, in render
    return nodelist.render(context)
  File "/opt/env_list/env_myblog/lib/python3.6/site-packages/django/template/base.py", line 937, in render
    bit = node.render_annotated(context)
  File "/opt/env_list/env_myblog/lib/python3.6/site-packages/django/template/base.py", line 904, in render_annotated
    return self.render(context)
  File "/opt/env_list/env_myblog/lib/python3.6/site-packages/django/template/defaulttags.py", line 200, in render
    .format(num_loopvars, len_item),
ValueError: Need 2 values to unpack in for loop; got 3. 
[2020-11-12 00:47:56,550] [log.py:228] [log:log_response] [WARNING]- Not Found: /index.php
[2020-11-12 00:47:56,572] [log.py:228] [log:log_response] [WARNING]- Not Found: /phpmyadmin/index.php
[2020-11-12 00:48:51,052] [log.py:228] [log:log_response] [ERROR]- Internal Server Error: /new_user/activity/2.html
Traceback (most recent call last):
  File "/opt/env_list/env_myblog/lib/python3.6/site-packages/django/core/handlers/exception.py", line 34, in inner
    response = get_response(request)
  File "/opt/env_list/env_myblog/lib/python3.6/site-packages/django/core/handlers/base.py", line 126, in _get_response
    response = self.process_exception_by_middleware(e, request)
  File "/opt/env_list/env_myblog/lib/python3.6/site-packages/django/core/handlers/base.py", line 124, in _get_response
    response = wrapped_callback(request, *callback_args, **callback_kwargs)
  File "./new_user/views.py", line 101, in activityView
    key = BadmintonActivity.objects.get(activity_number_id=int(number))
  File "/opt/env_list/env_myblog/lib/python3.6/site-packages/django/db/models/manager.py", line 82, in manager_method
    return getattr(self.get_queryset(), name)(*args, **kwargs)
  File "/opt/env_list/env_myblog/lib/python3.6/site-packages/django/db/models/query.py", line 390, in get
    clone = self.filter(*args, **kwargs)
  File "/opt/env_list/env_myblog/lib/python3.6/site-packages/django/db/models/query.py", line 844, in filter
    return self._filter_or_exclude(False, *args, **kwargs)
  File "/opt/env_list/env_myblog/lib/python3.6/site-packages/django/db/models/query.py", line 862, in _filter_or_exclude
    clone.query.add_q(Q(*args, **kwargs))
  File "/opt/env_list/env_myblog/lib/python3.6/site-packages/django/db/models/sql/query.py", line 1263, in add_q
    clause, _ = self._add_q(q_object, self.used_aliases)
  File "/opt/env_list/env_myblog/lib/python3.6/site-packages/django/db/models/sql/query.py", line 1287, in _add_q
    split_subq=split_subq,
  File "/opt/env_list/env_myblog/lib/python3.6/site-packages/django/db/models/sql/query.py", line 1164, in build_filter
    lookups, parts, reffed_expression = self.solve_lookup_type(arg)
  File "/opt/env_list/env_myblog/lib/python3.6/site-packages/django/db/models/sql/query.py", line 1028, in solve_lookup_type
    _, field, _, lookup_parts = self.names_to_path(lookup_splitted, self.get_meta())
  File "/opt/env_list/env_myblog/lib/python3.6/site-packages/django/db/models/sql/query.py", line 1389, in names_to_path
    "Choices are: %s" % (name, ", ".join(available)))
django.core.exceptions.FieldError: Cannot resolve keyword 'activity_number_id' into field. Choices are: activity_end_time, activity_name, activity_number, activity_start_time, badmintonactivitydetails, id, is_alive
[2020-11-12 00:50:09,654] [log.py:228] [log:log_response] [WARNING]- Not Found: /currentsetting.htm
[2020-11-12 00:52:49,143] [log.py:228] [log:log_response] [WARNING]- Not Found: /login.php
[2020-11-12 00:54:56,069] [log.py:228] [log:log_response] [WARNING]- Not Found: /login.php
[2020-11-12 00:54:56,075] [log.py:228] [log:log_response] [WARNING]- Not Found: /login.php
[2020-11-12 01:00:15,190] [log.py:228] [log:log_response] [ERROR]- Internal Server Error: /new_user/activity/2.html
Traceback (most recent call last):
  File "/opt/env_list/env_myblog/lib/python3.6/site-packages/django/core/handlers/exception.py", line 34, in inner
    response = get_response(request)
  File "/opt/env_list/env_myblog/lib/python3.6/site-packages/django/core/handlers/base.py", line 126, in _get_response
    response = self.process_exception_by_middleware(e, request)
  File "/opt/env_list/env_myblog/lib/python3.6/site-packages/django/core/handlers/base.py", line 124, in _get_response
    response = wrapped_callback(request, *callback_args, **callback_kwargs)
  File "./new_user/views.py", line 102, in activityView
    value = MyUser.objects.get(id=i.join_weChat_id).values('weChat')
AttributeError: 'MyUser' object has no attribute 'values'
[2020-11-12 01:00:33,841] [log.py:228] [log:log_response] [ERROR]- Internal Server Error: /new_user/activity/2.html
Traceback (most recent call last):
  File "/opt/env_list/env_myblog/lib/python3.6/site-packages/django/core/handlers/exception.py", line 34, in inner
    response = get_response(request)
  File "/opt/env_list/env_myblog/lib/python3.6/site-packages/django/core/handlers/base.py", line 126, in _get_response
    response = self.process_exception_by_middleware(e, request)
  File "/opt/env_list/env_myblog/lib/python3.6/site-packages/django/core/handlers/base.py", line 124, in _get_response
    response = wrapped_callback(request, *callback_args, **callback_kwargs)
  File "./new_user/views.py", line 102, in activityView
    value = MyUser.objects.get(id=i.join_weChat_id).value('weChat')
AttributeError: 'MyUser' object has no attribute 'value'
[2020-11-12 01:02:44,629] [log.py:228] [log:log_response] [ERROR]- Internal Server Error: /new_user/activity/2.html
Traceback (most recent call last):
  File "/opt/env_list/env_myblog/lib/python3.6/site-packages/django/core/handlers/exception.py", line 34, in inner
    response = get_response(request)
  File "/opt/env_list/env_myblog/lib/python3.6/site-packages/django/core/handlers/base.py", line 126, in _get_response
    response = self.process_exception_by_middleware(e, request)
  File "/opt/env_list/env_myblog/lib/python3.6/site-packages/django/core/handlers/base.py", line 124, in _get_response
    response = wrapped_callback(request, *callback_args, **callback_kwargs)
  File "./new_user/views.py", line 102, in activityView
    value = MyUser.objects.get(id=i.join_weChat_id).values_list('weChat')
AttributeError: 'MyUser' object has no attribute 'values_list'
[2020-11-12 01:03:34,686] [log.py:228] [log:log_response] [ERROR]- Internal Server Error: /new_user/activity/2.html
Traceback (most recent call last):
  File "/opt/env_list/env_myblog/lib/python3.6/site-packages/django/db/models/sql/query.py", line 1732, in add_fields
    join_info = self.setup_joins(name.split(LOOKUP_SEP), opts, alias, allow_many=allow_m2m)
  File "/opt/env_list/env_myblog/lib/python3.6/site-packages/django/db/models/sql/query.py", line 1473, in setup_joins
    names[:pivot], opts, allow_many, fail_on_missing=True,
  File "/opt/env_list/env_myblog/lib/python3.6/site-packages/django/db/models/sql/query.py", line 1389, in names_to_path
    "Choices are: %s" % (name, ", ".join(available)))
django.core.exceptions.FieldError: Cannot resolve keyword 'weChat[0]' into field. Choices are: article, badmintonactivitydetails, date_joined, email, first_name, groups, id, is_active, is_staff, is_superuser, last_login, last_name, logentry, password, user_permissions, username, weChat

During handling of the above exception, another exception occurred:

Traceback (most recent call last):
  File "/opt/env_list/env_myblog/lib/python3.6/site-packages/django/core/handlers/exception.py", line 34, in inner
    response = get_response(request)
  File "/opt/env_list/env_myblog/lib/python3.6/site-packages/django/core/handlers/base.py", line 126, in _get_response
    response = self.process_exception_by_middleware(e, request)
  File "/opt/env_list/env_myblog/lib/python3.6/site-packages/django/core/handlers/base.py", line 124, in _get_response
    response = wrapped_callback(request, *callback_args, **callback_kwargs)
  File "./new_user/views.py", line 102, in activityView
    value = MyUser.objects.filter(id=i.join_weChat_id).values_list('weChat[0]')
  File "/opt/env_list/env_myblog/lib/python3.6/site-packages/django/db/models/query.py", line 777, in values_list
    clone = self._values(*_fields, **expressions)
  File "/opt/env_list/env_myblog/lib/python3.6/site-packages/django/db/models/query.py", line 745, in _values
    clone.query.set_values(fields)
  File "/opt/env_list/env_myblog/lib/python3.6/site-packages/django/db/models/sql/query.py", line 1984, in set_values
    self.add_fields(field_names, True)
  File "/opt/env_list/env_myblog/lib/python3.6/site-packages/django/db/models/sql/query.py", line 1755, in add_fields
    "Choices are: %s" % (name, ", ".join(names)))
django.core.exceptions.FieldError: Cannot resolve keyword 'weChat[0]' into field. Choices are: article, badmintonactivitydetails, date_joined, email, first_name, groups, id, is_active, is_staff, is_superuser, last_login, last_name, logentry, password, user_permissions, username, weChat
[2020-11-12 01:03:50,729] [log.py:228] [log:log_response] [ERROR]- Internal Server Error: /new_user/activity/2.html
Traceback (most recent call last):
  File "/opt/env_list/env_myblog/lib/python3.6/site-packages/django/db/models/sql/query.py", line 1732, in add_fields
    join_info = self.setup_joins(name.split(LOOKUP_SEP), opts, alias, allow_many=allow_m2m)
  File "/opt/env_list/env_myblog/lib/python3.6/site-packages/django/db/models/sql/query.py", line 1473, in setup_joins
    names[:pivot], opts, allow_many, fail_on_missing=True,
  File "/opt/env_list/env_myblog/lib/python3.6/site-packages/django/db/models/sql/query.py", line 1389, in names_to_path
    "Choices are: %s" % (name, ", ".join(available)))
django.core.exceptions.FieldError: Cannot resolve keyword 'w' into field. Choices are: article, badmintonactivitydetails, date_joined, email, first_name, groups, id, is_active, is_staff, is_superuser, last_login, last_name, logentry, password, user_permissions, username, weChat

During handling of the above exception, another exception occurred:

Traceback (most recent call last):
  File "/opt/env_list/env_myblog/lib/python3.6/site-packages/django/core/handlers/exception.py", line 34, in inner
    response = get_response(request)
  File "/opt/env_list/env_myblog/lib/python3.6/site-packages/django/core/handlers/base.py", line 126, in _get_response
    response = self.process_exception_by_middleware(e, request)
  File "/opt/env_list/env_myblog/lib/python3.6/site-packages/django/core/handlers/base.py", line 124, in _get_response
    response = wrapped_callback(request, *callback_args, **callback_kwargs)
  File "./new_user/views.py", line 102, in activityView
    value = MyUser.objects.filter(id=i.join_weChat_id).values_list('weChat'[0])
  File "/opt/env_list/env_myblog/lib/python3.6/site-packages/django/db/models/query.py", line 777, in values_list
    clone = self._values(*_fields, **expressions)
  File "/opt/env_list/env_myblog/lib/python3.6/site-packages/django/db/models/query.py", line 745, in _values
    clone.query.set_values(fields)
  File "/opt/env_list/env_myblog/lib/python3.6/site-packages/django/db/models/sql/query.py", line 1984, in set_values
    self.add_fields(field_names, True)
  File "/opt/env_list/env_myblog/lib/python3.6/site-packages/django/db/models/sql/query.py", line 1755, in add_fields
    "Choices are: %s" % (name, ", ".join(names)))
django.core.exceptions.FieldError: Cannot resolve keyword 'w' into field. Choices are: article, badmintonactivitydetails, date_joined, email, first_name, groups, id, is_active, is_staff, is_superuser, last_login, last_name, logentry, password, user_permissions, username, weChat
[2020-11-12 01:04:35,577] [log.py:228] [log:log_response] [ERROR]- Internal Server Error: /new_user/activity/2.html
Traceback (most recent call last):
  File "/opt/env_list/env_myblog/lib/python3.6/site-packages/django/db/models/sql/query.py", line 1732, in add_fields
    join_info = self.setup_joins(name.split(LOOKUP_SEP), opts, alias, allow_many=allow_m2m)
  File "/opt/env_list/env_myblog/lib/python3.6/site-packages/django/db/models/sql/query.py", line 1473, in setup_joins
    names[:pivot], opts, allow_many, fail_on_missing=True,
  File "/opt/env_list/env_myblog/lib/python3.6/site-packages/django/db/models/sql/query.py", line 1389, in names_to_path
    "Choices are: %s" % (name, ", ".join(available)))
django.core.exceptions.FieldError: Cannot resolve keyword 'w' into field. Choices are: article, badmintonactivitydetails, date_joined, email, first_name, groups, id, is_active, is_staff, is_superuser, last_login, last_name, logentry, password, user_permissions, username, weChat

During handling of the above exception, another exception occurred:

Traceback (most recent call last):
  File "/opt/env_list/env_myblog/lib/python3.6/site-packages/django/core/handlers/exception.py", line 34, in inner
    response = get_response(request)
  File "/opt/env_list/env_myblog/lib/python3.6/site-packages/django/core/handlers/base.py", line 126, in _get_response
    response = self.process_exception_by_middleware(e, request)
  File "/opt/env_list/env_myblog/lib/python3.6/site-packages/django/core/handlers/base.py", line 124, in _get_response
    response = wrapped_callback(request, *callback_args, **callback_kwargs)
  File "./new_user/views.py", line 102, in activityView
    value = MyUser.objects.filter(id=i.join_weChat_id).values_list('weChat'[0])
  File "/opt/env_list/env_myblog/lib/python3.6/site-packages/django/db/models/query.py", line 777, in values_list
    clone = self._values(*_fields, **expressions)
  File "/opt/env_list/env_myblog/lib/python3.6/site-packages/django/db/models/query.py", line 745, in _values
    clone.query.set_values(fields)
  File "/opt/env_list/env_myblog/lib/python3.6/site-packages/django/db/models/sql/query.py", line 1984, in set_values
    self.add_fields(field_names, True)
  File "/opt/env_list/env_myblog/lib/python3.6/site-packages/django/db/models/sql/query.py", line 1755, in add_fields
    "Choices are: %s" % (name, ", ".join(names)))
django.core.exceptions.FieldError: Cannot resolve keyword 'w' into field. Choices are: article, badmintonactivitydetails, date_joined, email, first_name, groups, id, is_active, is_staff, is_superuser, last_login, last_name, logentry, password, user_permissions, username, weChat
[2020-11-12 01:04:37,289] [log.py:228] [log:log_response] [ERROR]- Internal Server Error: /new_user/activity/2.html
Traceback (most recent call last):
  File "/opt/env_list/env_myblog/lib/python3.6/site-packages/django/db/models/sql/query.py", line 1732, in add_fields
    join_info = self.setup_joins(name.split(LOOKUP_SEP), opts, alias, allow_many=allow_m2m)
  File "/opt/env_list/env_myblog/lib/python3.6/site-packages/django/db/models/sql/query.py", line 1473, in setup_joins
    names[:pivot], opts, allow_many, fail_on_missing=True,
  File "/opt/env_list/env_myblog/lib/python3.6/site-packages/django/db/models/sql/query.py", line 1389, in names_to_path
    "Choices are: %s" % (name, ", ".join(available)))
django.core.exceptions.FieldError: Cannot resolve keyword 'w' into field. Choices are: article, badmintonactivitydetails, date_joined, email, first_name, groups, id, is_active, is_staff, is_superuser, last_login, last_name, logentry, password, user_permissions, username, weChat

During handling of the above exception, another exception occurred:

Traceback (most recent call last):
  File "/opt/env_list/env_myblog/lib/python3.6/site-packages/django/core/handlers/exception.py", line 34, in inner
    response = get_response(request)
  File "/opt/env_list/env_myblog/lib/python3.6/site-packages/django/core/handlers/base.py", line 126, in _get_response
    response = self.process_exception_by_middleware(e, request)
  File "/opt/env_list/env_myblog/lib/python3.6/site-packages/django/core/handlers/base.py", line 124, in _get_response
    response = wrapped_callback(request, *callback_args, **callback_kwargs)
  File "./new_user/views.py", line 102, in activityView
    value = MyUser.objects.filter(id=i.join_weChat_id).values_list('weChat'[0])
  File "/opt/env_list/env_myblog/lib/python3.6/site-packages/django/db/models/query.py", line 777, in values_list
    clone = self._values(*_fields, **expressions)
  File "/opt/env_list/env_myblog/lib/python3.6/site-packages/django/db/models/query.py", line 745, in _values
    clone.query.set_values(fields)
  File "/opt/env_list/env_myblog/lib/python3.6/site-packages/django/db/models/sql/query.py", line 1984, in set_values
    self.add_fields(field_names, True)
  File "/opt/env_list/env_myblog/lib/python3.6/site-packages/django/db/models/sql/query.py", line 1755, in add_fields
    "Choices are: %s" % (name, ", ".join(names)))
django.core.exceptions.FieldError: Cannot resolve keyword 'w' into field. Choices are: article, badmintonactivitydetails, date_joined, email, first_name, groups, id, is_active, is_staff, is_superuser, last_login, last_name, logentry, password, user_permissions, username, weChat
[2020-11-12 01:06:15,402] [log.py:228] [log:log_response] [ERROR]- Internal Server Error: /new_user/activity/2.html
Traceback (most recent call last):
  File "/opt/env_list/env_myblog/lib/python3.6/site-packages/django/core/handlers/exception.py", line 34, in inner
    response = get_response(request)
  File "/opt/env_list/env_myblog/lib/python3.6/site-packages/django/core/handlers/base.py", line 126, in _get_response
    response = self.process_exception_by_middleware(e, request)
  File "/opt/env_list/env_myblog/lib/python3.6/site-packages/django/core/handlers/base.py", line 124, in _get_response
    response = wrapped_callback(request, *callback_args, **callback_kwargs)
  File "./new_user/views.py", line 100, in activityView
    for i in activityDetails:
TypeError: 'BadmintonActivityDetails' object is not iterable
[2020-11-12 01:06:48,453] [log.py:228] [log:log_response] [ERROR]- Internal Server Error: /new_user/activity/2.html
Traceback (most recent call last):
  File "/opt/env_list/env_myblog/lib/python3.6/site-packages/django/core/handlers/exception.py", line 34, in inner
    response = get_response(request)
  File "/opt/env_list/env_myblog/lib/python3.6/site-packages/django/core/handlers/base.py", line 126, in _get_response
    response = self.process_exception_by_middleware(e, request)
  File "/opt/env_list/env_myblog/lib/python3.6/site-packages/django/core/handlers/base.py", line 124, in _get_response
    response = wrapped_callback(request, *callback_args, **callback_kwargs)
  File "./new_user/views.py", line 102, in activityView
    value = MyUser.objects.get(id=i.join_weChat_id).values_list('weChat')
AttributeError: 'MyUser' object has no attribute 'values_list'
[2020-11-12 01:12:56,084] [log.py:228] [log:log_response] [WARNING]- Not Found: /favicon.ico
[2020-11-12 02:10:27,340] [log.py:228] [log:log_response] [WARNING]- Not Found: /data/admin/allowurl.txt
[2020-11-12 02:22:18,931] [log.py:228] [log:log_response] [WARNING]- Not Found: /guanli/login.php
[2020-11-12 03:40:49,685] [log.py:228] [log:log_response] [WARNING]- Not Found: /cache/global/img/gs.gif
[2020-11-12 04:13:17,656] [log.py:228] [log:log_response] [WARNING]- Not Found: /GponForm/diag_Form
[2020-11-12 05:06:50,978] [log.py:228] [log:log_response] [WARNING]- Not Found: /hudson
[2020-11-12 05:38:55,060] [log.py:228] [log:log_response] [WARNING]- Not Found: /currentsetting.htm
[2020-11-12 07:02:02,230] [log.py:228] [log:log_response] [WARNING]- Not Found: /boaform/admin/formLogin
[2020-11-12 08:33:35,399] [log.py:228] [log:log_response] [WARNING]- Not Found: /data/admin/allowurl.txt
[2020-11-12 10:25:55,118] [log.py:228] [log:log_response] [WARNING]- Not Found: /.env
[2020-11-12 10:25:55,662] [log.py:228] [log:log_response] [WARNING]- Forbidden (CSRF cookie not set.): /
[2020-11-12 10:31:36,586] [log.py:228] [log:log_response] [WARNING]- Not Found: /currentsetting.htm
[2020-11-12 10:56:54,389] [log.py:228] [log:log_response] [WARNING]- Not Found: /favicon.ico
[2020-11-12 11:38:25,987] [log.py:228] [log:log_response] [WARNING]- Not Found: /favicon.ico
[2020-11-12 12:18:51,351] [log.py:228] [log:log_response] [WARNING]- Not Found: /favicon.ico
